{
 "cells": [
  {
   "cell_type": "code",
   "execution_count": 1,
   "metadata": {},
   "outputs": [],
   "source": [
    "import toweb\n",
    "s=toweb.Server(\"test\")"
   ]
  },
  {
   "cell_type": "code",
   "execution_count": 2,
   "metadata": {},
   "outputs": [
    {
     "name": "stdout",
     "output_type": "stream",
     "text": [
      "Please open http://localhost:8000/view/test\n"
     ]
    },
    {
     "data": {
      "text/html": [
       "\n",
       "        <iframe\n",
       "            width=\"100%\"\n",
       "            height=\"600px\"\n",
       "            src=\"http://localhost:8000/view/test\"\n",
       "            frameborder=\"0\"\n",
       "            allowfullscreen\n",
       "        ></iframe>\n",
       "        "
      ],
      "text/plain": [
       "<IPython.lib.display.IFrame at 0x7f59dc3115e0>"
      ]
     },
     "metadata": {},
     "output_type": "display_data"
    },
    {
     "name": "stderr",
     "output_type": "stream",
     "text": [
      "--- Logging error ---\n",
      "--- Logging error ---\n",
      "--- Logging error ---\n",
      "--- Logging error ---\n",
      "--- Logging error ---\n",
      "Exception in thread Thread-4:\n",
      "Traceback (most recent call last):\n",
      "  File \"/home/tumiz/.local/lib/python3.8/site-packages/tornado/web.py\", line 1703, in _execute\n",
      "    result = await result\n",
      "  File \"/home/tumiz/.local/lib/python3.8/site-packages/tornado/websocket.py\", line 278, in get\n",
      "    await self.ws_connection.accept_connection(self)\n",
      "  File \"/home/tumiz/.local/lib/python3.8/site-packages/tornado/websocket.py\", line 881, in accept_connection\n",
      "    await self._accept_connection(handler)\n",
      "  File \"/home/tumiz/.local/lib/python3.8/site-packages/tornado/websocket.py\", line 964, in _accept_connection\n",
      "    await self._receive_frame_loop()\n",
      "  File \"/home/tumiz/.local/lib/python3.8/site-packages/tornado/websocket.py\", line 1121, in _receive_frame_loop\n",
      "    self.handler.on_ws_connection_close(self.close_code, self.close_reason)\n",
      "  File \"/home/tumiz/.local/lib/python3.8/site-packages/tornado/websocket.py\", line 578, in on_ws_connection_close\n",
      "    self.on_connection_close()\n",
      "  File \"/home/tumiz/.local/lib/python3.8/site-packages/tornado/websocket.py\", line 570, in on_connection_close\n",
      "    self.on_close()\n",
      "  File \"/mnt/d/codes/scenario/toweb/toweb/server.py\", line 49, in on_close\n",
      "AttributeError: 'WSHandler' object has no attribute 'server'\n",
      "\n",
      "During handling of the above exception, another exception occurred:\n",
      "\n",
      "Traceback (most recent call last):\n",
      "  File \"/home/tumiz/anaconda3/lib/python3.8/logging/__init__.py\", line 1081, in emit\n",
      "    msg = self.format(record)\n",
      "  File \"/home/tumiz/anaconda3/lib/python3.8/logging/__init__.py\", line 925, in format\n",
      "    return fmt.format(record)\n",
      "  File \"/home/tumiz/anaconda3/lib/python3.8/logging/__init__.py\", line 672, in format\n",
      "    record.exc_text = self.formatException(record.exc_info)\n",
      "  File \"/home/tumiz/anaconda3/lib/python3.8/logging/__init__.py\", line 622, in formatException\n",
      "    traceback.print_exception(ei[0], ei[1], tb, None, sio)\n",
      "  File \"/home/tumiz/anaconda3/lib/python3.8/traceback.py\", line 103, in print_exception\n",
      "    for line in TracebackException(\n",
      "  File \"/home/tumiz/anaconda3/lib/python3.8/traceback.py\", line 509, in __init__\n",
      "    self.stack = StackSummary.extract(\n",
      "  File \"/home/tumiz/anaconda3/lib/python3.8/traceback.py\", line 366, in extract\n",
      "    f.line\n",
      "  File \"/home/tumiz/anaconda3/lib/python3.8/traceback.py\", line 288, in line\n",
      "    self._line = linecache.getline(self.filename, self.lineno).strip()\n",
      "  File \"/home/tumiz/anaconda3/lib/python3.8/linecache.py\", line 16, in getline\n",
      "    lines = getlines(filename, module_globals)\n",
      "  File \"/home/tumiz/anaconda3/lib/python3.8/linecache.py\", line 47, in getlines\n",
      "    return updatecache(filename, module_globals)\n",
      "  File \"/home/tumiz/anaconda3/lib/python3.8/linecache.py\", line 137, in updatecache\n",
      "    lines = fp.readlines()\n",
      "  File \"/home/tumiz/anaconda3/lib/python3.8/codecs.py\", line 322, in decode\n",
      "    (result, consumed) = self._buffer_decode(data, self.errors, final)\n",
      "UnicodeDecodeError: 'utf-8' codec can't decode byte 0xd4 in position 3494: invalid continuation byte\n",
      "\n",
      "During handling of the above exception, another exception occurred:\n",
      "\n",
      "Traceback (most recent call last):\n",
      "  File \"/home/tumiz/.local/lib/python3.8/site-packages/tornado/web.py\", line 1752, in _handle_request_exception\n",
      "    self.log_exception(*sys.exc_info())\n",
      "  File \"/home/tumiz/.local/lib/python3.8/site-packages/tornado/web.py\", line 1788, in log_exception\n",
      "    app_log.error(  # type: ignore\n",
      "  File \"/home/tumiz/anaconda3/lib/python3.8/logging/__init__.py\", line 1463, in error\n",
      "    self._log(ERROR, msg, args, **kwargs)\n",
      "  File \"/home/tumiz/anaconda3/lib/python3.8/logging/__init__.py\", line 1577, in _log\n",
      "    self.handle(record)\n",
      "  File \"/home/tumiz/anaconda3/lib/python3.8/logging/__init__.py\", line 1587, in handle\n",
      "    self.callHandlers(record)\n",
      "  File \"/home/tumiz/anaconda3/lib/python3.8/logging/__init__.py\", line 1649, in callHandlers\n",
      "    hdlr.handle(record)\n",
      "  File \"/home/tumiz/anaconda3/lib/python3.8/logging/__init__.py\", line 950, in handle\n",
      "    self.emit(record)\n",
      "  File \"/home/tumiz/anaconda3/lib/python3.8/logging/__init__.py\", line 1089, in emit\n",
      "    self.handleError(record)\n",
      "  File \"/home/tumiz/anaconda3/lib/python3.8/logging/__init__.py\", line 1003, in handleError\n",
      "    traceback.print_exception(t, v, tb, None, sys.stderr)\n",
      "  File \"/home/tumiz/anaconda3/lib/python3.8/traceback.py\", line 103, in print_exception\n",
      "    for line in TracebackException(\n",
      "  File \"/home/tumiz/anaconda3/lib/python3.8/traceback.py\", line 524, in __init__\n",
      "    self._load_lines()\n",
      "  File \"/home/tumiz/anaconda3/lib/python3.8/traceback.py\", line 536, in _load_lines\n",
      "    self.__context__._load_lines()\n",
      "  File \"/home/tumiz/anaconda3/lib/python3.8/traceback.py\", line 534, in _load_lines\n",
      "    frame.line\n",
      "  File \"/home/tumiz/anaconda3/lib/python3.8/traceback.py\", line 288, in line\n",
      "    self._line = linecache.getline(self.filename, self.lineno).strip()\n",
      "  File \"/home/tumiz/anaconda3/lib/python3.8/linecache.py\", line 16, in getline\n",
      "    lines = getlines(filename, module_globals)\n",
      "  File \"/home/tumiz/anaconda3/lib/python3.8/linecache.py\", line 47, in getlines\n",
      "    return updatecache(filename, module_globals)\n",
      "  File \"/home/tumiz/anaconda3/lib/python3.8/linecache.py\", line 137, in updatecache\n",
      "    lines = fp.readlines()\n",
      "  File \"/home/tumiz/anaconda3/lib/python3.8/codecs.py\", line 322, in decode\n",
      "    (result, consumed) = self._buffer_decode(data, self.errors, final)\n",
      "UnicodeDecodeError: 'utf-8' codec can't decode byte 0xd4 in position 3494: invalid continuation byte\n",
      "\n",
      "During handling of the above exception, another exception occurred:\n",
      "\n",
      "Traceback (most recent call last):\n",
      "  File \"/home/tumiz/anaconda3/lib/python3.8/logging/__init__.py\", line 1081, in emit\n",
      "    msg = self.format(record)\n",
      "  File \"/home/tumiz/anaconda3/lib/python3.8/logging/__init__.py\", line 925, in format\n",
      "    return fmt.format(record)\n",
      "  File \"/home/tumiz/anaconda3/lib/python3.8/logging/__init__.py\", line 672, in format\n",
      "    record.exc_text = self.formatException(record.exc_info)\n",
      "  File \"/home/tumiz/anaconda3/lib/python3.8/logging/__init__.py\", line 622, in formatException\n",
      "    traceback.print_exception(ei[0], ei[1], tb, None, sio)\n",
      "  File \"/home/tumiz/anaconda3/lib/python3.8/traceback.py\", line 103, in print_exception\n",
      "    for line in TracebackException(\n",
      "  File \"/home/tumiz/anaconda3/lib/python3.8/traceback.py\", line 524, in __init__\n",
      "    self._load_lines()\n",
      "  File \"/home/tumiz/anaconda3/lib/python3.8/traceback.py\", line 536, in _load_lines\n",
      "    self.__context__._load_lines()\n",
      "  File \"/home/tumiz/anaconda3/lib/python3.8/traceback.py\", line 536, in _load_lines\n",
      "    self.__context__._load_lines()\n",
      "  File \"/home/tumiz/anaconda3/lib/python3.8/traceback.py\", line 534, in _load_lines\n",
      "    frame.line\n",
      "  File \"/home/tumiz/anaconda3/lib/python3.8/traceback.py\", line 288, in line\n",
      "    self._line = linecache.getline(self.filename, self.lineno).strip()\n",
      "  File \"/home/tumiz/anaconda3/lib/python3.8/linecache.py\", line 16, in getline\n",
      "    lines = getlines(filename, module_globals)\n",
      "  File \"/home/tumiz/anaconda3/lib/python3.8/linecache.py\", line 47, in getlines\n",
      "    return updatecache(filename, module_globals)\n",
      "  File \"/home/tumiz/anaconda3/lib/python3.8/linecache.py\", line 137, in updatecache\n",
      "    lines = fp.readlines()\n",
      "  File \"/home/tumiz/anaconda3/lib/python3.8/codecs.py\", line 322, in decode\n",
      "    (result, consumed) = self._buffer_decode(data, self.errors, final)\n",
      "UnicodeDecodeError: 'utf-8' codec can't decode byte 0xd4 in position 3494: invalid continuation byte\n",
      "\n",
      "During handling of the above exception, another exception occurred:\n",
      "\n",
      "Traceback (most recent call last):\n",
      "  File \"/home/tumiz/.local/lib/python3.8/site-packages/tornado/web.py\", line 1708, in _execute\n",
      "    self._handle_request_exception(e)\n",
      "  File \"/home/tumiz/.local/lib/python3.8/site-packages/tornado/web.py\", line 1756, in _handle_request_exception\n",
      "    app_log.error(\"Error in exception logger\", exc_info=True)\n",
      "  File \"/home/tumiz/anaconda3/lib/python3.8/logging/__init__.py\", line 1463, in error\n",
      "    self._log(ERROR, msg, args, **kwargs)\n",
      "  File \"/home/tumiz/anaconda3/lib/python3.8/logging/__init__.py\", line 1577, in _log\n",
      "    self.handle(record)\n",
      "  File \"/home/tumiz/anaconda3/lib/python3.8/logging/__init__.py\", line 1587, in handle\n",
      "    self.callHandlers(record)\n",
      "  File \"/home/tumiz/anaconda3/lib/python3.8/logging/__init__.py\", line 1649, in callHandlers\n",
      "    hdlr.handle(record)\n",
      "  File \"/home/tumiz/anaconda3/lib/python3.8/logging/__init__.py\", line 950, in handle\n",
      "    self.emit(record)\n",
      "  File \"/home/tumiz/anaconda3/lib/python3.8/logging/__init__.py\", line 1089, in emit\n",
      "    self.handleError(record)\n",
      "  File \"/home/tumiz/anaconda3/lib/python3.8/logging/__init__.py\", line 1003, in handleError\n",
      "    traceback.print_exception(t, v, tb, None, sys.stderr)\n",
      "  File \"/home/tumiz/anaconda3/lib/python3.8/traceback.py\", line 103, in print_exception\n",
      "    for line in TracebackException(\n",
      "  File \"/home/tumiz/anaconda3/lib/python3.8/traceback.py\", line 524, in __init__\n",
      "    self._load_lines()\n",
      "  File \"/home/tumiz/anaconda3/lib/python3.8/traceback.py\", line 536, in _load_lines\n",
      "    self.__context__._load_lines()\n",
      "  File \"/home/tumiz/anaconda3/lib/python3.8/traceback.py\", line 536, in _load_lines\n",
      "    self.__context__._load_lines()\n",
      "  File \"/home/tumiz/anaconda3/lib/python3.8/traceback.py\", line 536, in _load_lines\n",
      "    self.__context__._load_lines()\n",
      "  File \"/home/tumiz/anaconda3/lib/python3.8/traceback.py\", line 534, in _load_lines\n",
      "    frame.line\n",
      "  File \"/home/tumiz/anaconda3/lib/python3.8/traceback.py\", line 288, in line\n",
      "    self._line = linecache.getline(self.filename, self.lineno).strip()\n",
      "  File \"/home/tumiz/anaconda3/lib/python3.8/linecache.py\", line 16, in getline\n",
      "    lines = getlines(filename, module_globals)\n",
      "  File \"/home/tumiz/anaconda3/lib/python3.8/linecache.py\", line 47, in getlines\n",
      "    return updatecache(filename, module_globals)\n",
      "  File \"/home/tumiz/anaconda3/lib/python3.8/linecache.py\", line 137, in updatecache\n",
      "    lines = fp.readlines()\n",
      "  File \"/home/tumiz/anaconda3/lib/python3.8/codecs.py\", line 322, in decode\n",
      "    (result, consumed) = self._buffer_decode(data, self.errors, final)\n",
      "UnicodeDecodeError: 'utf-8' codec can't decode byte 0xd4 in position 3494: invalid continuation byte\n",
      "\n",
      "During handling of the above exception, another exception occurred:\n",
      "\n",
      "Traceback (most recent call last):\n",
      "  File \"/home/tumiz/anaconda3/lib/python3.8/logging/__init__.py\", line 1081, in emit\n",
      "    msg = self.format(record)\n",
      "  File \"/home/tumiz/anaconda3/lib/python3.8/logging/__init__.py\", line 925, in format\n",
      "    return fmt.format(record)\n",
      "  File \"/home/tumiz/anaconda3/lib/python3.8/logging/__init__.py\", line 672, in format\n",
      "    record.exc_text = self.formatException(record.exc_info)\n",
      "  File \"/home/tumiz/anaconda3/lib/python3.8/logging/__init__.py\", line 622, in formatException\n",
      "    traceback.print_exception(ei[0], ei[1], tb, None, sio)\n",
      "  File \"/home/tumiz/anaconda3/lib/python3.8/traceback.py\", line 103, in print_exception\n",
      "    for line in TracebackException(\n",
      "  File \"/home/tumiz/anaconda3/lib/python3.8/traceback.py\", line 524, in __init__\n",
      "    self._load_lines()\n",
      "  File \"/home/tumiz/anaconda3/lib/python3.8/traceback.py\", line 536, in _load_lines\n",
      "    self.__context__._load_lines()\n",
      "  File \"/home/tumiz/anaconda3/lib/python3.8/traceback.py\", line 536, in _load_lines\n",
      "    self.__context__._load_lines()\n",
      "  File \"/home/tumiz/anaconda3/lib/python3.8/traceback.py\", line 536, in _load_lines\n",
      "    self.__context__._load_lines()\n",
      "  [Previous line repeated 1 more time]\n",
      "  File \"/home/tumiz/anaconda3/lib/python3.8/traceback.py\", line 534, in _load_lines\n",
      "    frame.line\n",
      "  File \"/home/tumiz/anaconda3/lib/python3.8/traceback.py\", line 288, in line\n",
      "    self._line = linecache.getline(self.filename, self.lineno).strip()\n",
      "  File \"/home/tumiz/anaconda3/lib/python3.8/linecache.py\", line 16, in getline\n",
      "    lines = getlines(filename, module_globals)\n",
      "  File \"/home/tumiz/anaconda3/lib/python3.8/linecache.py\", line 47, in getlines\n",
      "    return updatecache(filename, module_globals)\n",
      "  File \"/home/tumiz/anaconda3/lib/python3.8/linecache.py\", line 137, in updatecache\n",
      "    lines = fp.readlines()\n",
      "  File \"/home/tumiz/anaconda3/lib/python3.8/codecs.py\", line 322, in decode\n",
      "    (result, consumed) = self._buffer_decode(data, self.errors, final)\n",
      "UnicodeDecodeError: 'utf-8' codec can't decode byte 0xd4 in position 3494: invalid continuation byte\n",
      "\n",
      "During handling of the above exception, another exception occurred:\n",
      "\n",
      "Traceback (most recent call last):\n",
      "  File \"/home/tumiz/anaconda3/lib/python3.8/asyncio/events.py\", line 81, in _run\n",
      "    self._context.run(self._callback, *self._args)\n",
      "  File \"/home/tumiz/.local/lib/python3.8/site-packages/tornado/web.py\", line 2333, in <lambda>\n",
      "    fut.add_done_callback(lambda f: f.result())\n",
      "  File \"/home/tumiz/.local/lib/python3.8/site-packages/tornado/web.py\", line 1710, in _execute\n",
      "    app_log.error(\"Exception in exception handler\", exc_info=True)\n",
      "  File \"/home/tumiz/anaconda3/lib/python3.8/logging/__init__.py\", line 1463, in error\n",
      "    self._log(ERROR, msg, args, **kwargs)\n",
      "  File \"/home/tumiz/anaconda3/lib/python3.8/logging/__init__.py\", line 1577, in _log\n",
      "    self.handle(record)\n",
      "  File \"/home/tumiz/anaconda3/lib/python3.8/logging/__init__.py\", line 1587, in handle\n",
      "    self.callHandlers(record)\n",
      "  File \"/home/tumiz/anaconda3/lib/python3.8/logging/__init__.py\", line 1649, in callHandlers\n",
      "    hdlr.handle(record)\n",
      "  File \"/home/tumiz/anaconda3/lib/python3.8/logging/__init__.py\", line 950, in handle\n",
      "    self.emit(record)\n",
      "  File \"/home/tumiz/anaconda3/lib/python3.8/logging/__init__.py\", line 1089, in emit\n",
      "    self.handleError(record)\n",
      "  File \"/home/tumiz/anaconda3/lib/python3.8/logging/__init__.py\", line 1003, in handleError\n",
      "    traceback.print_exception(t, v, tb, None, sys.stderr)\n",
      "  File \"/home/tumiz/anaconda3/lib/python3.8/traceback.py\", line 103, in print_exception\n",
      "    for line in TracebackException(\n",
      "  File \"/home/tumiz/anaconda3/lib/python3.8/traceback.py\", line 524, in __init__\n",
      "    self._load_lines()\n",
      "  File \"/home/tumiz/anaconda3/lib/python3.8/traceback.py\", line 536, in _load_lines\n",
      "    self.__context__._load_lines()\n",
      "  File \"/home/tumiz/anaconda3/lib/python3.8/traceback.py\", line 536, in _load_lines\n",
      "    self.__context__._load_lines()\n",
      "  File \"/home/tumiz/anaconda3/lib/python3.8/traceback.py\", line 536, in _load_lines\n",
      "    self.__context__._load_lines()\n",
      "  [Previous line repeated 2 more times]\n",
      "  File \"/home/tumiz/anaconda3/lib/python3.8/traceback.py\", line 534, in _load_lines\n",
      "    frame.line\n",
      "  File \"/home/tumiz/anaconda3/lib/python3.8/traceback.py\", line 288, in line\n",
      "    self._line = linecache.getline(self.filename, self.lineno).strip()\n",
      "  File \"/home/tumiz/anaconda3/lib/python3.8/linecache.py\", line 16, in getline\n",
      "    lines = getlines(filename, module_globals)\n",
      "  File \"/home/tumiz/anaconda3/lib/python3.8/linecache.py\", line 47, in getlines\n",
      "    return updatecache(filename, module_globals)\n",
      "  File \"/home/tumiz/anaconda3/lib/python3.8/linecache.py\", line 137, in updatecache\n",
      "    lines = fp.readlines()\n",
      "  File \"/home/tumiz/anaconda3/lib/python3.8/codecs.py\", line 322, in decode\n",
      "    (result, consumed) = self._buffer_decode(data, self.errors, final)\n",
      "UnicodeDecodeError: 'utf-8' codec can't decode byte 0xd4 in position 3494: invalid continuation byte\n",
      "\n",
      "During handling of the above exception, another exception occurred:\n",
      "\n",
      "Traceback (most recent call last):\n",
      "  File \"/home/tumiz/anaconda3/lib/python3.8/logging/__init__.py\", line 1081, in emit\n",
      "    msg = self.format(record)\n",
      "  File \"/home/tumiz/anaconda3/lib/python3.8/logging/__init__.py\", line 925, in format\n",
      "    return fmt.format(record)\n",
      "  File \"/home/tumiz/anaconda3/lib/python3.8/logging/__init__.py\", line 672, in format\n",
      "    record.exc_text = self.formatException(record.exc_info)\n",
      "  File \"/home/tumiz/anaconda3/lib/python3.8/logging/__init__.py\", line 622, in formatException\n",
      "    traceback.print_exception(ei[0], ei[1], tb, None, sio)\n",
      "  File \"/home/tumiz/anaconda3/lib/python3.8/traceback.py\", line 103, in print_exception\n",
      "    for line in TracebackException(\n",
      "  File \"/home/tumiz/anaconda3/lib/python3.8/traceback.py\", line 524, in __init__\n",
      "    self._load_lines()\n",
      "  File \"/home/tumiz/anaconda3/lib/python3.8/traceback.py\", line 536, in _load_lines\n",
      "    self.__context__._load_lines()\n",
      "  File \"/home/tumiz/anaconda3/lib/python3.8/traceback.py\", line 536, in _load_lines\n",
      "    self.__context__._load_lines()\n",
      "  File \"/home/tumiz/anaconda3/lib/python3.8/traceback.py\", line 536, in _load_lines\n",
      "    self.__context__._load_lines()\n",
      "  [Previous line repeated 3 more times]\n",
      "  File \"/home/tumiz/anaconda3/lib/python3.8/traceback.py\", line 534, in _load_lines\n",
      "    frame.line\n",
      "  File \"/home/tumiz/anaconda3/lib/python3.8/traceback.py\", line 288, in line\n",
      "    self._line = linecache.getline(self.filename, self.lineno).strip()\n",
      "  File \"/home/tumiz/anaconda3/lib/python3.8/linecache.py\", line 16, in getline\n",
      "    lines = getlines(filename, module_globals)\n",
      "  File \"/home/tumiz/anaconda3/lib/python3.8/linecache.py\", line 47, in getlines\n",
      "    return updatecache(filename, module_globals)\n",
      "  File \"/home/tumiz/anaconda3/lib/python3.8/linecache.py\", line 137, in updatecache\n",
      "    lines = fp.readlines()\n",
      "  File \"/home/tumiz/anaconda3/lib/python3.8/codecs.py\", line 322, in decode\n",
      "    (result, consumed) = self._buffer_decode(data, self.errors, final)\n",
      "UnicodeDecodeError: 'utf-8' codec can't decode byte 0xd4 in position 3494: invalid continuation byte\n",
      "\n",
      "During handling of the above exception, another exception occurred:\n",
      "\n",
      "Traceback (most recent call last):\n",
      "  File \"/home/tumiz/anaconda3/lib/python3.8/asyncio/base_events.py\", line 1733, in call_exception_handler\n",
      "    self.default_exception_handler(context)\n",
      "  File \"/home/tumiz/anaconda3/lib/python3.8/asyncio/base_events.py\", line 1707, in default_exception_handler\n",
      "    logger.error('\\n'.join(log_lines), exc_info=exc_info)\n",
      "  File \"/home/tumiz/anaconda3/lib/python3.8/logging/__init__.py\", line 1463, in error\n",
      "    self._log(ERROR, msg, args, **kwargs)\n",
      "  File \"/home/tumiz/anaconda3/lib/python3.8/logging/__init__.py\", line 1577, in _log\n",
      "    self.handle(record)\n",
      "  File \"/home/tumiz/anaconda3/lib/python3.8/logging/__init__.py\", line 1587, in handle\n",
      "    self.callHandlers(record)\n",
      "  File \"/home/tumiz/anaconda3/lib/python3.8/logging/__init__.py\", line 1657, in callHandlers\n",
      "    lastResort.handle(record)\n",
      "  File \"/home/tumiz/anaconda3/lib/python3.8/logging/__init__.py\", line 950, in handle\n",
      "    self.emit(record)\n",
      "  File \"/home/tumiz/anaconda3/lib/python3.8/logging/__init__.py\", line 1089, in emit\n",
      "    self.handleError(record)\n",
      "  File \"/home/tumiz/anaconda3/lib/python3.8/logging/__init__.py\", line 1003, in handleError\n",
      "    traceback.print_exception(t, v, tb, None, sys.stderr)\n",
      "  File \"/home/tumiz/anaconda3/lib/python3.8/traceback.py\", line 103, in print_exception\n",
      "    for line in TracebackException(\n",
      "  File \"/home/tumiz/anaconda3/lib/python3.8/traceback.py\", line 524, in __init__\n",
      "    self._load_lines()\n",
      "  File \"/home/tumiz/anaconda3/lib/python3.8/traceback.py\", line 536, in _load_lines\n",
      "    self.__context__._load_lines()\n",
      "  File \"/home/tumiz/anaconda3/lib/python3.8/traceback.py\", line 536, in _load_lines\n",
      "    self.__context__._load_lines()\n",
      "  File \"/home/tumiz/anaconda3/lib/python3.8/traceback.py\", line 536, in _load_lines\n",
      "    self.__context__._load_lines()\n",
      "  [Previous line repeated 4 more times]\n",
      "  File \"/home/tumiz/anaconda3/lib/python3.8/traceback.py\", line 534, in _load_lines\n",
      "    frame.line\n",
      "  File \"/home/tumiz/anaconda3/lib/python3.8/traceback.py\", line 288, in line\n",
      "    self._line = linecache.getline(self.filename, self.lineno).strip()\n",
      "  File \"/home/tumiz/anaconda3/lib/python3.8/linecache.py\", line 16, in getline\n",
      "    lines = getlines(filename, module_globals)\n",
      "  File \"/home/tumiz/anaconda3/lib/python3.8/linecache.py\", line 47, in getlines\n",
      "    return updatecache(filename, module_globals)\n",
      "  File \"/home/tumiz/anaconda3/lib/python3.8/linecache.py\", line 137, in updatecache\n",
      "    lines = fp.readlines()\n",
      "  File \"/home/tumiz/anaconda3/lib/python3.8/codecs.py\", line 322, in decode\n",
      "    (result, consumed) = self._buffer_decode(data, self.errors, final)\n",
      "UnicodeDecodeError: 'utf-8' codec can't decode byte 0xd4 in position 3494: invalid continuation byte\n",
      "\n",
      "During handling of the above exception, another exception occurred:\n",
      "\n",
      "Traceback (most recent call last):\n",
      "  File \"/home/tumiz/anaconda3/lib/python3.8/logging/__init__.py\", line 1081, in emit\n",
      "    msg = self.format(record)\n",
      "  File \"/home/tumiz/anaconda3/lib/python3.8/logging/__init__.py\", line 925, in format\n",
      "    return fmt.format(record)\n",
      "  File \"/home/tumiz/anaconda3/lib/python3.8/logging/__init__.py\", line 672, in format\n",
      "    record.exc_text = self.formatException(record.exc_info)\n",
      "  File \"/home/tumiz/anaconda3/lib/python3.8/logging/__init__.py\", line 622, in formatException\n",
      "    traceback.print_exception(ei[0], ei[1], tb, None, sio)\n",
      "  File \"/home/tumiz/anaconda3/lib/python3.8/traceback.py\", line 103, in print_exception\n",
      "    for line in TracebackException(\n",
      "  File \"/home/tumiz/anaconda3/lib/python3.8/traceback.py\", line 524, in __init__\n",
      "    self._load_lines()\n",
      "  File \"/home/tumiz/anaconda3/lib/python3.8/traceback.py\", line 536, in _load_lines\n",
      "    self.__context__._load_lines()\n",
      "  File \"/home/tumiz/anaconda3/lib/python3.8/traceback.py\", line 536, in _load_lines\n",
      "    self.__context__._load_lines()\n",
      "  File \"/home/tumiz/anaconda3/lib/python3.8/traceback.py\", line 536, in _load_lines\n",
      "    self.__context__._load_lines()\n",
      "  [Previous line repeated 5 more times]\n",
      "  File \"/home/tumiz/anaconda3/lib/python3.8/traceback.py\", line 534, in _load_lines\n",
      "    frame.line\n",
      "  File \"/home/tumiz/anaconda3/lib/python3.8/traceback.py\", line 288, in line\n",
      "    self._line = linecache.getline(self.filename, self.lineno).strip()\n",
      "  File \"/home/tumiz/anaconda3/lib/python3.8/linecache.py\", line 16, in getline\n",
      "    lines = getlines(filename, module_globals)\n",
      "  File \"/home/tumiz/anaconda3/lib/python3.8/linecache.py\", line 47, in getlines\n",
      "    return updatecache(filename, module_globals)\n",
      "  File \"/home/tumiz/anaconda3/lib/python3.8/linecache.py\", line 137, in updatecache\n",
      "    lines = fp.readlines()\n",
      "  File \"/home/tumiz/anaconda3/lib/python3.8/codecs.py\", line 322, in decode\n",
      "    (result, consumed) = self._buffer_decode(data, self.errors, final)\n",
      "UnicodeDecodeError: 'utf-8' codec can't decode byte 0xd4 in position 3494: invalid continuation byte\n",
      "\n",
      "During handling of the above exception, another exception occurred:\n",
      "\n",
      "Traceback (most recent call last):\n",
      "  File \"/home/tumiz/anaconda3/lib/python3.8/threading.py\", line 932, in _bootstrap_inner\n",
      "    self.run()\n",
      "  File \"/home/tumiz/anaconda3/lib/python3.8/threading.py\", line 870, in run\n",
      "    self._target(*self._args, **self._kwargs)\n",
      "  File \"/mnt/d/codes/scenario/toweb/toweb/server.py\", line 139, in run\n",
      "  File \"/home/tumiz/.local/lib/python3.8/site-packages/tornado/platform/asyncio.py\", line 149, in start\n",
      "    self.asyncio_loop.run_forever()\n",
      "  File \"/home/tumiz/anaconda3/lib/python3.8/asyncio/base_events.py\", line 570, in run_forever\n",
      "    self._run_once()\n",
      "  File \"/home/tumiz/anaconda3/lib/python3.8/asyncio/base_events.py\", line 1859, in _run_once\n",
      "    handle._run()\n",
      "  File \"/home/tumiz/anaconda3/lib/python3.8/asyncio/events.py\", line 95, in _run\n",
      "    self._loop.call_exception_handler(context)\n",
      "  File \"/home/tumiz/anaconda3/lib/python3.8/asyncio/base_events.py\", line 1740, in call_exception_handler\n",
      "    logger.error('Exception in default exception handler',\n",
      "  File \"/home/tumiz/anaconda3/lib/python3.8/logging/__init__.py\", line 1463, in error\n",
      "    self._log(ERROR, msg, args, **kwargs)\n",
      "  File \"/home/tumiz/anaconda3/lib/python3.8/logging/__init__.py\", line 1577, in _log\n",
      "    self.handle(record)\n",
      "  File \"/home/tumiz/anaconda3/lib/python3.8/logging/__init__.py\", line 1587, in handle\n",
      "    self.callHandlers(record)\n",
      "  File \"/home/tumiz/anaconda3/lib/python3.8/logging/__init__.py\", line 1657, in callHandlers\n",
      "    lastResort.handle(record)\n",
      "  File \"/home/tumiz/anaconda3/lib/python3.8/logging/__init__.py\", line 950, in handle\n",
      "    self.emit(record)\n",
      "  File \"/home/tumiz/anaconda3/lib/python3.8/logging/__init__.py\", line 1089, in emit\n",
      "    self.handleError(record)\n",
      "  File \"/home/tumiz/anaconda3/lib/python3.8/logging/__init__.py\", line 1003, in handleError\n",
      "    traceback.print_exception(t, v, tb, None, sys.stderr)\n",
      "  File \"/home/tumiz/anaconda3/lib/python3.8/traceback.py\", line 103, in print_exception\n",
      "    for line in TracebackException(\n",
      "  File \"/home/tumiz/anaconda3/lib/python3.8/traceback.py\", line 524, in __init__\n",
      "    self._load_lines()\n",
      "  File \"/home/tumiz/anaconda3/lib/python3.8/traceback.py\", line 536, in _load_lines\n",
      "    self.__context__._load_lines()\n",
      "  File \"/home/tumiz/anaconda3/lib/python3.8/traceback.py\", line 536, in _load_lines\n",
      "    self.__context__._load_lines()\n",
      "  File \"/home/tumiz/anaconda3/lib/python3.8/traceback.py\", line 536, in _load_lines\n",
      "    self.__context__._load_lines()\n",
      "  [Previous line repeated 6 more times]\n",
      "  File \"/home/tumiz/anaconda3/lib/python3.8/traceback.py\", line 534, in _load_lines\n",
      "    frame.line\n",
      "  File \"/home/tumiz/anaconda3/lib/python3.8/traceback.py\", line 288, in line\n",
      "    self._line = linecache.getline(self.filename, self.lineno).strip()\n",
      "  File \"/home/tumiz/anaconda3/lib/python3.8/linecache.py\", line 16, in getline\n",
      "    lines = getlines(filename, module_globals)\n",
      "  File \"/home/tumiz/anaconda3/lib/python3.8/linecache.py\", line 47, in getlines\n",
      "    return updatecache(filename, module_globals)\n",
      "  File \"/home/tumiz/anaconda3/lib/python3.8/linecache.py\", line 137, in updatecache\n",
      "    lines = fp.readlines()\n",
      "  File \"/home/tumiz/anaconda3/lib/python3.8/codecs.py\", line 322, in decode\n",
      "    (result, consumed) = self._buffer_decode(data, self.errors, final)\n",
      "UnicodeDecodeError: 'utf-8' codec can't decode byte 0xd4 in position 3494: invalid continuation byte\n"
     ]
    }
   ],
   "source": [
    "s.clear()\n",
    "for i in range(100):\n",
    "    s.plot(i,i*i/100)\n",
    "    if i%2==0:\n",
    "        s.err(2, \"times\")\n",
    "    elif i%3==0:\n",
    "        s.warn(3, \"times\")\n",
    "    else:\n",
    "        s.info(\"normal\")"
   ]
  }
 ],
 "metadata": {
  "interpreter": {
   "hash": "f977ab77590a1a82c6ed99bad9ba7e44f59b6349cfa3ab98a372fb69dd4e7d34"
  },
  "kernelspec": {
   "display_name": "Python 3.8.3 64-bit ('base': conda)",
   "name": "python3"
  },
  "language_info": {
   "name": "python",
   "version": ""
  }
 },
 "nbformat": 4,
 "nbformat_minor": 4
}